2022-09-05 20:07:41,554 ERROR: Exception on /login [POST] [in /Library/Frameworks/Python.framework/Versions/3.10/lib/python3.10/site-packages/flask/app.py:1457]
Traceback (most recent call last):
  File "/Library/Frameworks/Python.framework/Versions/3.10/lib/python3.10/site-packages/flask/app.py", line 2073, in wsgi_app
    response = self.full_dispatch_request()
  File "/Library/Frameworks/Python.framework/Versions/3.10/lib/python3.10/site-packages/flask/app.py", line 1518, in full_dispatch_request
    rv = self.handle_user_exception(e)
  File "/Library/Frameworks/Python.framework/Versions/3.10/lib/python3.10/site-packages/flask/app.py", line 1516, in full_dispatch_request
    rv = self.dispatch_request()
  File "/Library/Frameworks/Python.framework/Versions/3.10/lib/python3.10/site-packages/flask/app.py", line 1502, in dispatch_request
    return self.ensure_sync(self.view_functions[rule.endpoint])(**req.view_args)
  File "/Users/mauro.sagace/SynologyDrive/Datenbanken- und Web Entwicklung_MySQL/microblog_Grundgeruest/WebAPP-2022/microblog/app/routes.py", line 89, in login
    if user is None or not user.check_password(form.password.data):
  File "/Users/mauro.sagace/SynologyDrive/Datenbanken- und Web Entwicklung_MySQL/microblog_Grundgeruest/WebAPP-2022/microblog/app/models.py", line 36, in check_password
    return check_password_hash(self.password_hash, password)
  File "/Library/Frameworks/Python.framework/Versions/3.10/lib/python3.10/site-packages/werkzeug/security.py", line 215, in check_password_hash
    if pwhash.count("$") < 2:
AttributeError: 'NoneType' object has no attribute 'count'
2022-09-05 20:07:55,235 ERROR: Exception on /login [POST] [in /Library/Frameworks/Python.framework/Versions/3.10/lib/python3.10/site-packages/flask/app.py:1457]
Traceback (most recent call last):
  File "/Library/Frameworks/Python.framework/Versions/3.10/lib/python3.10/site-packages/flask/app.py", line 2073, in wsgi_app
    response = self.full_dispatch_request()
  File "/Library/Frameworks/Python.framework/Versions/3.10/lib/python3.10/site-packages/flask/app.py", line 1518, in full_dispatch_request
    rv = self.handle_user_exception(e)
  File "/Library/Frameworks/Python.framework/Versions/3.10/lib/python3.10/site-packages/flask/app.py", line 1516, in full_dispatch_request
    rv = self.dispatch_request()
  File "/Library/Frameworks/Python.framework/Versions/3.10/lib/python3.10/site-packages/flask/app.py", line 1502, in dispatch_request
    return self.ensure_sync(self.view_functions[rule.endpoint])(**req.view_args)
  File "/Users/mauro.sagace/SynologyDrive/Datenbanken- und Web Entwicklung_MySQL/microblog_Grundgeruest/WebAPP-2022/microblog/app/routes.py", line 89, in login
    if user is None or not user.check_password(form.password.data):
  File "/Users/mauro.sagace/SynologyDrive/Datenbanken- und Web Entwicklung_MySQL/microblog_Grundgeruest/WebAPP-2022/microblog/app/models.py", line 36, in check_password
    return check_password_hash(self.password_hash, password)
  File "/Library/Frameworks/Python.framework/Versions/3.10/lib/python3.10/site-packages/werkzeug/security.py", line 215, in check_password_hash
    if pwhash.count("$") < 2:
AttributeError: 'NoneType' object has no attribute 'count'
2022-09-05 20:08:22,203 ERROR: Exception on /user/Test1 [GET] [in /Library/Frameworks/Python.framework/Versions/3.10/lib/python3.10/site-packages/flask/app.py:1457]
Traceback (most recent call last):
  File "/Library/Frameworks/Python.framework/Versions/3.10/lib/python3.10/site-packages/flask/app.py", line 2073, in wsgi_app
    response = self.full_dispatch_request()
  File "/Library/Frameworks/Python.framework/Versions/3.10/lib/python3.10/site-packages/flask/app.py", line 1518, in full_dispatch_request
    rv = self.handle_user_exception(e)
  File "/Library/Frameworks/Python.framework/Versions/3.10/lib/python3.10/site-packages/flask/app.py", line 1516, in full_dispatch_request
    rv = self.dispatch_request()
  File "/Library/Frameworks/Python.framework/Versions/3.10/lib/python3.10/site-packages/flask/app.py", line 1502, in dispatch_request
    return self.ensure_sync(self.view_functions[rule.endpoint])(**req.view_args)
  File "/Library/Frameworks/Python.framework/Versions/3.10/lib/python3.10/site-packages/flask_login/utils.py", line 272, in decorated_view
    return func(*args, **kwargs)
  File "/Users/mauro.sagace/SynologyDrive/Datenbanken- und Web Entwicklung_MySQL/microblog_Grundgeruest/WebAPP-2022/microblog/app/routes.py", line 169, in user
    return render_template('user.html', title='User', user=user, lines=dates.items)
  File "/Library/Frameworks/Python.framework/Versions/3.10/lib/python3.10/site-packages/flask/templating.py", line 147, in render_template
    return _render(
  File "/Library/Frameworks/Python.framework/Versions/3.10/lib/python3.10/site-packages/flask/templating.py", line 128, in _render
    rv = template.render(context)
  File "/Library/Frameworks/Python.framework/Versions/3.10/lib/python3.10/site-packages/jinja2/environment.py", line 1291, in render
    self.environment.handle_exception()
  File "/Library/Frameworks/Python.framework/Versions/3.10/lib/python3.10/site-packages/jinja2/environment.py", line 926, in handle_exception
    raise rewrite_traceback_stack(source=source)
  File "/Users/mauro.sagace/SynologyDrive/Datenbanken- und Web Entwicklung_MySQL/microblog_Grundgeruest/WebAPP-2022/microblog/app/templates/user.html", line 1, in top-level template code
    {% extends "base.html" %}
  File "/Users/mauro.sagace/SynologyDrive/Datenbanken- und Web Entwicklung_MySQL/microblog_Grundgeruest/WebAPP-2022/microblog/app/templates/base.html", line 1, in top-level template code
    {% extends 'bootstrap/base.html' %}
  File "/Library/Frameworks/Python.framework/Versions/3.10/lib/python3.10/site-packages/flask_bootstrap/templates/bootstrap/base.html", line 1, in top-level template code
    {% block doc -%}
  File "/Library/Frameworks/Python.framework/Versions/3.10/lib/python3.10/site-packages/flask_bootstrap/templates/bootstrap/base.html", line 4, in block 'doc'
    {%- block html %}
  File "/Library/Frameworks/Python.framework/Versions/3.10/lib/python3.10/site-packages/flask_bootstrap/templates/bootstrap/base.html", line 20, in block 'html'
    {% block body -%}
  File "/Library/Frameworks/Python.framework/Versions/3.10/lib/python3.10/site-packages/flask_bootstrap/templates/bootstrap/base.html", line 23, in block 'body'
    {% block content -%}
  File "/Users/mauro.sagace/SynologyDrive/Datenbanken- und Web Entwicklung_MySQL/microblog_Grundgeruest/WebAPP-2022/microblog/app/templates/base.html", line 54, in block 'content'
    {% block app_content %}{% endblock %}
  File "/Users/mauro.sagace/SynologyDrive/Datenbanken- und Web Entwicklung_MySQL/microblog_Grundgeruest/WebAPP-2022/microblog/app/templates/user.html", line 21, in block 'app_content'
    <a href="{{ url_for('delete_reservations', weeks_id=line.id) }}">stornieren</a>
  File "/Library/Frameworks/Python.framework/Versions/3.10/lib/python3.10/site-packages/flask/helpers.py", line 338, in url_for
    return appctx.app.handle_url_build_error(error, endpoint, values)
  File "/Library/Frameworks/Python.framework/Versions/3.10/lib/python3.10/site-packages/flask/helpers.py", line 325, in url_for
    rv = url_adapter.build(
  File "/Library/Frameworks/Python.framework/Versions/3.10/lib/python3.10/site-packages/werkzeug/routing.py", line 2315, in build
    raise BuildError(endpoint, values, method, self)
werkzeug.routing.BuildError: Could not build url for endpoint 'delete_reservations' with values ['weeks_id']. Did you mean 'delete' instead?
2022-09-05 20:13:31,051 INFO: Microblog startup [in /Users/mauro.sagace/SynologyDrive/Datenbanken- und Web Entwicklung_MySQL/microblog_Grundgeruest/WebAPP-2022/microblog/app/__init__.py:47]
